2025-07-04 11:50:32,325 INFO    StreamThr :29364 [internal.py:wandb_internal():85] W&B internal server running at pid: 29364, started at: 2025-07-04 11:50:32.324134
2025-07-04 11:50:32,327 DEBUG   HandlerThread:29364 [handler.py:handle_request():158] handle_request: status
2025-07-04 11:50:32,330 INFO    WriterThread:29364 [datastore.py:open_for_write():87] open: D:\YOLO\yolo11-up\42_demo\wandb\run-20250704_115032-52g9f2wk\run-52g9f2wk.wandb
2025-07-04 11:50:32,330 DEBUG   SenderThread:29364 [sender.py:send():391] send: header
2025-07-04 11:50:32,332 DEBUG   SenderThread:29364 [sender.py:send():391] send: run
2025-07-04 11:50:37,348 DEBUG   HandlerThread:29364 [handler.py:handle_request():158] handle_request: keepalive
2025-07-04 11:50:42,403 DEBUG   HandlerThread:29364 [handler.py:handle_request():158] handle_request: keepalive
2025-07-04 11:50:47,455 DEBUG   HandlerThread:29364 [handler.py:handle_request():158] handle_request: keepalive
2025-07-04 11:50:52,507 DEBUG   HandlerThread:29364 [handler.py:handle_request():158] handle_request: keepalive
2025-07-04 11:50:57,544 DEBUG   HandlerThread:29364 [handler.py:handle_request():158] handle_request: keepalive
2025-07-04 11:51:02,583 DEBUG   HandlerThread:29364 [handler.py:handle_request():158] handle_request: keepalive
2025-07-04 11:51:07,607 DEBUG   HandlerThread:29364 [handler.py:handle_request():158] handle_request: keepalive
2025-07-04 11:51:12,634 DEBUG   HandlerThread:29364 [handler.py:handle_request():158] handle_request: keepalive
2025-07-04 11:51:17,698 DEBUG   HandlerThread:29364 [handler.py:handle_request():158] handle_request: keepalive
2025-07-04 11:51:22,758 DEBUG   HandlerThread:29364 [handler.py:handle_request():158] handle_request: keepalive
2025-07-04 11:51:27,824 DEBUG   HandlerThread:29364 [handler.py:handle_request():158] handle_request: keepalive
2025-07-04 11:51:32,872 DEBUG   HandlerThread:29364 [handler.py:handle_request():158] handle_request: keepalive
2025-07-04 11:51:35,862 INFO    SenderThread:29364 [retry.py:__call__():172] Retry attempt failed:
Traceback (most recent call last):
  File "C:\Users\huangshengqi\.conda\envs\dsjtl\lib\site-packages\urllib3\connection.py", line 174, in _new_conn
    conn = connection.create_connection(
  File "C:\Users\huangshengqi\.conda\envs\dsjtl\lib\site-packages\urllib3\util\connection.py", line 95, in create_connection
    raise err
  File "C:\Users\huangshengqi\.conda\envs\dsjtl\lib\site-packages\urllib3\util\connection.py", line 85, in create_connection
    sock.connect(sa)
socket.timeout: timed out

During handling of the above exception, another exception occurred:

Traceback (most recent call last):
  File "C:\Users\huangshengqi\.conda\envs\dsjtl\lib\site-packages\urllib3\connectionpool.py", line 715, in urlopen
    httplib_response = self._make_request(
  File "C:\Users\huangshengqi\.conda\envs\dsjtl\lib\site-packages\urllib3\connectionpool.py", line 404, in _make_request
    self._validate_conn(conn)
  File "C:\Users\huangshengqi\.conda\envs\dsjtl\lib\site-packages\urllib3\connectionpool.py", line 1058, in _validate_conn
    conn.connect()
  File "C:\Users\huangshengqi\.conda\envs\dsjtl\lib\site-packages\urllib3\connection.py", line 363, in connect
    self.sock = conn = self._new_conn()
  File "C:\Users\huangshengqi\.conda\envs\dsjtl\lib\site-packages\urllib3\connection.py", line 179, in _new_conn
    raise ConnectTimeoutError(
urllib3.exceptions.ConnectTimeoutError: (<urllib3.connection.HTTPSConnection object at 0x000001A56EA7AB80>, 'Connection to api.wandb.ai timed out. (connect timeout=20)')

During handling of the above exception, another exception occurred:

Traceback (most recent call last):
  File "C:\Users\huangshengqi\.conda\envs\dsjtl\lib\site-packages\requests\adapters.py", line 486, in send
    resp = conn.urlopen(
  File "C:\Users\huangshengqi\.conda\envs\dsjtl\lib\site-packages\urllib3\connectionpool.py", line 799, in urlopen
    retries = retries.increment(
  File "C:\Users\huangshengqi\.conda\envs\dsjtl\lib\site-packages\urllib3\util\retry.py", line 592, in increment
    raise MaxRetryError(_pool, url, error or ResponseError(cause))
urllib3.exceptions.MaxRetryError: HTTPSConnectionPool(host='api.wandb.ai', port=443): Max retries exceeded with url: /graphql (Caused by ConnectTimeoutError(<urllib3.connection.HTTPSConnection object at 0x000001A56EA7AB80>, 'Connection to api.wandb.ai timed out. (connect timeout=20)'))

During handling of the above exception, another exception occurred:

Traceback (most recent call last):
  File "C:\Users\huangshengqi\AppData\Roaming\Python\Python38\site-packages\wandb\sdk\lib\retry.py", line 131, in __call__
    result = self._call_fn(*args, **kwargs)
  File "C:\Users\huangshengqi\AppData\Roaming\Python\Python38\site-packages\wandb\sdk\internal\internal_api.py", line 345, in execute
    return self.client.execute(*args, **kwargs)  # type: ignore
  File "C:\Users\huangshengqi\AppData\Roaming\Python\Python38\site-packages\wandb\vendor\gql-0.2.0\wandb_gql\client.py", line 52, in execute
    result = self._get_result(document, *args, **kwargs)
  File "C:\Users\huangshengqi\AppData\Roaming\Python\Python38\site-packages\wandb\vendor\gql-0.2.0\wandb_gql\client.py", line 60, in _get_result
    return self.transport.execute(document, *args, **kwargs)
  File "C:\Users\huangshengqi\AppData\Roaming\Python\Python38\site-packages\wandb\sdk\lib\gql_request.py", line 58, in execute
    request = self.session.post(self.url, **post_args)
  File "C:\Users\huangshengqi\.conda\envs\dsjtl\lib\site-packages\requests\sessions.py", line 637, in post
    return self.request("POST", url, data=data, json=json, **kwargs)
  File "C:\Users\huangshengqi\.conda\envs\dsjtl\lib\site-packages\requests\sessions.py", line 589, in request
    resp = self.send(prep, **send_kwargs)
  File "C:\Users\huangshengqi\.conda\envs\dsjtl\lib\site-packages\requests\sessions.py", line 703, in send
    r = adapter.send(request, **kwargs)
  File "C:\Users\huangshengqi\.conda\envs\dsjtl\lib\site-packages\requests\adapters.py", line 507, in send
    raise ConnectTimeout(e, request=request)
requests.exceptions.ConnectTimeout: HTTPSConnectionPool(host='api.wandb.ai', port=443): Max retries exceeded with url: /graphql (Caused by ConnectTimeoutError(<urllib3.connection.HTTPSConnection object at 0x000001A56EA7AB80>, 'Connection to api.wandb.ai timed out. (connect timeout=20)'))
2025-07-04 11:51:37,921 DEBUG   HandlerThread:29364 [handler.py:handle_request():158] handle_request: keepalive
2025-07-04 11:51:42,975 DEBUG   HandlerThread:29364 [handler.py:handle_request():158] handle_request: keepalive
2025-07-04 11:51:48,032 DEBUG   HandlerThread:29364 [handler.py:handle_request():158] handle_request: keepalive
2025-07-04 11:51:53,092 DEBUG   HandlerThread:29364 [handler.py:handle_request():158] handle_request: keepalive
2025-07-04 11:51:58,127 DEBUG   HandlerThread:29364 [handler.py:handle_request():158] handle_request: keepalive
2025-07-04 11:52:03,170 DEBUG   HandlerThread:29364 [handler.py:handle_request():158] handle_request: cancel
2025-07-04 11:52:03,170 DEBUG   HandlerThread:29364 [handler.py:handle_request():158] handle_request: cancel
2025-07-04 11:52:03,171 DEBUG   SenderThread:29364 [sender.py:send():400] Record cancelled: run
2025-07-04 11:52:03,171 DEBUG   HandlerThread:29364 [handler.py:handle_request():158] handle_request: status_report
2025-07-04 11:52:05,212 DEBUG   HandlerThread:29364 [handler.py:handle_request():158] handle_request: shutdown
2025-07-04 11:52:05,212 INFO    HandlerThread:29364 [handler.py:finish():882] shutting down handler
2025-07-04 11:52:06,195 INFO    WriterThread:29364 [datastore.py:close():296] close: D:\YOLO\yolo11-up\42_demo\wandb\run-20250704_115032-52g9f2wk\run-52g9f2wk.wandb
2025-07-04 11:52:06,195 INFO    SenderThread:29364 [sender.py:finish():1631] shutting down sender
