2025-07-04 11:46:06,272 INFO    StreamThr :25256 [internal.py:wandb_internal():85] W&B internal server running at pid: 25256, started at: 2025-07-04 11:46:06.270935
2025-07-04 11:46:06,274 DEBUG   HandlerThread:25256 [handler.py:handle_request():158] handle_request: status
2025-07-04 11:46:06,278 INFO    WriterThread:25256 [datastore.py:open_for_write():87] open: D:\YOLO\yolo11-up\42_demo\wandb\run-20250704_114606-0exak388\run-0exak388.wandb
2025-07-04 11:46:06,279 DEBUG   SenderThread:25256 [sender.py:send():391] send: header
2025-07-04 11:46:06,280 DEBUG   SenderThread:25256 [sender.py:send():391] send: run
2025-07-04 11:46:10,331 INFO    SenderThread:25256 [retry.py:__call__():172] Retry attempt failed:
Traceback (most recent call last):
  File "C:\Users\huangshengqi\.conda\envs\dsjtl\lib\site-packages\urllib3\connectionpool.py", line 712, in urlopen
    self._prepare_proxy(conn)
  File "C:\Users\huangshengqi\.conda\envs\dsjtl\lib\site-packages\urllib3\connectionpool.py", line 1012, in _prepare_proxy
    conn.connect()
  File "C:\Users\huangshengqi\.conda\envs\dsjtl\lib\site-packages\urllib3\connection.py", line 369, in connect
    self.sock = conn = self._connect_tls_proxy(hostname, conn)
  File "C:\Users\huangshengqi\.conda\envs\dsjtl\lib\site-packages\urllib3\connection.py", line 504, in _connect_tls_proxy
    socket = ssl_wrap_socket(
  File "C:\Users\huangshengqi\.conda\envs\dsjtl\lib\site-packages\urllib3\util\ssl_.py", line 453, in ssl_wrap_socket
    ssl_sock = _ssl_wrap_socket_impl(sock, context, tls_in_tls)
  File "C:\Users\huangshengqi\.conda\envs\dsjtl\lib\site-packages\urllib3\util\ssl_.py", line 495, in _ssl_wrap_socket_impl
    return ssl_context.wrap_socket(sock)
  File "C:\Users\huangshengqi\.conda\envs\dsjtl\lib\ssl.py", line 500, in wrap_socket
    return self.sslsocket_class._create(
  File "C:\Users\huangshengqi\.conda\envs\dsjtl\lib\ssl.py", line 1073, in _create
    self.do_handshake()
  File "C:\Users\huangshengqi\.conda\envs\dsjtl\lib\ssl.py", line 1342, in do_handshake
    self._sslobj.do_handshake()
ssl.SSLZeroReturnError: TLS/SSL connection has been closed (EOF) (_ssl.c:1131)

During handling of the above exception, another exception occurred:

Traceback (most recent call last):
  File "C:\Users\huangshengqi\.conda\envs\dsjtl\lib\site-packages\requests\adapters.py", line 486, in send
    resp = conn.urlopen(
  File "C:\Users\huangshengqi\.conda\envs\dsjtl\lib\site-packages\urllib3\connectionpool.py", line 799, in urlopen
    retries = retries.increment(
  File "C:\Users\huangshengqi\.conda\envs\dsjtl\lib\site-packages\urllib3\util\retry.py", line 592, in increment
    raise MaxRetryError(_pool, url, error or ResponseError(cause))
urllib3.exceptions.MaxRetryError: HTTPSConnectionPool(host='api.wandb.ai', port=443): Max retries exceeded with url: /graphql (Caused by SSLError(SSLZeroReturnError(6, 'TLS/SSL connection has been closed (EOF) (_ssl.c:1131)')))

During handling of the above exception, another exception occurred:

Traceback (most recent call last):
  File "C:\Users\huangshengqi\AppData\Roaming\Python\Python38\site-packages\wandb\sdk\lib\retry.py", line 131, in __call__
    result = self._call_fn(*args, **kwargs)
  File "C:\Users\huangshengqi\AppData\Roaming\Python\Python38\site-packages\wandb\sdk\internal\internal_api.py", line 345, in execute
    return self.client.execute(*args, **kwargs)  # type: ignore
  File "C:\Users\huangshengqi\AppData\Roaming\Python\Python38\site-packages\wandb\vendor\gql-0.2.0\wandb_gql\client.py", line 52, in execute
    result = self._get_result(document, *args, **kwargs)
  File "C:\Users\huangshengqi\AppData\Roaming\Python\Python38\site-packages\wandb\vendor\gql-0.2.0\wandb_gql\client.py", line 60, in _get_result
    return self.transport.execute(document, *args, **kwargs)
  File "C:\Users\huangshengqi\AppData\Roaming\Python\Python38\site-packages\wandb\sdk\lib\gql_request.py", line 58, in execute
    request = self.session.post(self.url, **post_args)
  File "C:\Users\huangshengqi\.conda\envs\dsjtl\lib\site-packages\requests\sessions.py", line 637, in post
    return self.request("POST", url, data=data, json=json, **kwargs)
  File "C:\Users\huangshengqi\.conda\envs\dsjtl\lib\site-packages\requests\sessions.py", line 589, in request
    resp = self.send(prep, **send_kwargs)
  File "C:\Users\huangshengqi\.conda\envs\dsjtl\lib\site-packages\requests\sessions.py", line 703, in send
    r = adapter.send(request, **kwargs)
  File "C:\Users\huangshengqi\.conda\envs\dsjtl\lib\site-packages\requests\adapters.py", line 517, in send
    raise SSLError(e, request=request)
requests.exceptions.SSLError: HTTPSConnectionPool(host='api.wandb.ai', port=443): Max retries exceeded with url: /graphql (Caused by SSLError(SSLZeroReturnError(6, 'TLS/SSL connection has been closed (EOF) (_ssl.c:1131)')))
2025-07-04 11:46:11,328 DEBUG   HandlerThread:25256 [handler.py:handle_request():158] handle_request: keepalive
2025-07-04 11:46:16,381 DEBUG   HandlerThread:25256 [handler.py:handle_request():158] handle_request: keepalive
2025-07-04 11:46:21,421 DEBUG   HandlerThread:25256 [handler.py:handle_request():158] handle_request: keepalive
2025-07-04 11:46:26,480 DEBUG   HandlerThread:25256 [handler.py:handle_request():158] handle_request: keepalive
2025-07-04 11:46:31,531 DEBUG   HandlerThread:25256 [handler.py:handle_request():158] handle_request: keepalive
2025-07-04 11:46:36,585 DEBUG   HandlerThread:25256 [handler.py:handle_request():158] handle_request: keepalive
2025-07-04 11:46:41,606 DEBUG   HandlerThread:25256 [handler.py:handle_request():158] handle_request: keepalive
2025-07-04 11:46:46,659 DEBUG   HandlerThread:25256 [handler.py:handle_request():158] handle_request: keepalive
2025-07-04 11:46:51,713 DEBUG   HandlerThread:25256 [handler.py:handle_request():158] handle_request: keepalive
2025-07-04 11:46:56,761 DEBUG   HandlerThread:25256 [handler.py:handle_request():158] handle_request: keepalive
2025-07-04 11:47:01,805 DEBUG   HandlerThread:25256 [handler.py:handle_request():158] handle_request: keepalive
2025-07-04 11:47:06,871 DEBUG   HandlerThread:25256 [handler.py:handle_request():158] handle_request: keepalive
2025-07-04 11:47:11,909 DEBUG   HandlerThread:25256 [handler.py:handle_request():158] handle_request: keepalive
2025-07-04 11:47:16,937 DEBUG   HandlerThread:25256 [handler.py:handle_request():158] handle_request: keepalive
2025-07-04 11:47:21,987 DEBUG   HandlerThread:25256 [handler.py:handle_request():158] handle_request: keepalive
2025-07-04 11:47:27,030 DEBUG   HandlerThread:25256 [handler.py:handle_request():158] handle_request: keepalive
2025-07-04 11:47:32,082 DEBUG   HandlerThread:25256 [handler.py:handle_request():158] handle_request: keepalive
2025-07-04 11:47:37,143 DEBUG   HandlerThread:25256 [handler.py:handle_request():158] handle_request: cancel
2025-07-04 11:47:37,143 DEBUG   HandlerThread:25256 [handler.py:handle_request():158] handle_request: cancel
2025-07-04 11:47:37,144 DEBUG   SenderThread:25256 [sender.py:send():400] Record cancelled: run
2025-07-04 11:47:37,144 DEBUG   HandlerThread:25256 [handler.py:handle_request():158] handle_request: status_report
2025-07-04 11:47:39,180 DEBUG   HandlerThread:25256 [handler.py:handle_request():158] handle_request: shutdown
2025-07-04 11:47:39,180 INFO    HandlerThread:25256 [handler.py:finish():882] shutting down handler
2025-07-04 11:47:40,172 INFO    WriterThread:25256 [datastore.py:close():296] close: D:\YOLO\yolo11-up\42_demo\wandb\run-20250704_114606-0exak388\run-0exak388.wandb
2025-07-04 11:47:40,172 INFO    SenderThread:25256 [sender.py:finish():1631] shutting down sender
